Workbook

Sheet Imputs
B2: Risk Free Rate | C2: 0.0667
B3: ERP | C3: 0.0523
B6: 1 | C6: {=TRANSPOSE(Table2[#Headers])} -> NSE Ticker Symbol
B7: =B6+1 -> 2 | C7: Company Name
B8: =B7+1 -> 3 | C8: Sector
B9: =B8+1 -> 4 | C9: Industry
B10: =B9+1 -> 5 | C10: Market Capitalisation In(Cr)
B11: =B10+1 -> 6 | C11: Risk Free Rate
B12: =B11+1 -> 7 | C12: ERP
B13: =B12+1 -> 8 | C13: Daily Beta
B14: =B13+1 -> 9 | C14: Weekly Beta
B15: =B14+1 -> 10 | C15: Monthly Beta
B16: =B15+1 -> 11 | C16: Cost of Equity (Daily Beta)
B17: =B16+1 -> 12 | C17: Cost of Equity (Weekly Beta)
B18: =B17+1 -> 13 | C18: Cost of Equity (Monthly Beta)
... B26: =B25+1 -> 21 | C26: Weight of Debt
B27: =B26+1 -> 22 | C27: WACC (Daily) | E27: =MATCH("WACC (Daily)",Table2[#Headers],0) -> 22
B28: =B27+1 -> 23 | C28: WACC (Weekly) | E28: =MATCH("WACC (Daily)",Table2[#Headers],0) -> 22
B29: =B28+1 -> 24 | C29: WACC (Monthly) | E29: =MATCH("WACC (Daily)",Table2[#Headers],0) -> 22
B30: =B29+1 -> 25 | C30: Financial Services
B31: =B30+1 -> 26 | C31: FIRM TYPE
B32: =B31+1 -> 27

Sheet Analysis
B1: WACC OF STOCKS LISTED ON NSE
B2: NSE Ticker Symbol | C2: Company Name | D2: Sector | E2: Industry | F2: Market Capitalisation In(Cr) | G2: Risk Free Rate | H2: ERP | I2: Daily Beta | J2: Weekly Beta | K2: Monthly Beta | L2: Cost of Equity (Daily Beta) | M2: Cost of Equity (Weekly Beta) | N2: Cost of Equity (Monthly Beta) | O2: Interest Coverage Ratio | P2: Default Spread | Q2: Credit Rating (Acc to lookup table) | R2: Cost of Debt | S2: Market Value of Equity | T2: Market Value of Debt | U2: Weight of Equity | V2: Weight of Debt | W2: WACC (Daily) | X2: WACC (Weekly) | Y2: WACC (Monthly) | Z2: Financial Services | AA2: FIRM TYPE
B3: NAGAFERT | C3: =_xlfn.XLOOKUP(B3,stock_analysis[Stock],stock_analysis[Company_Name]) -> Nagarjuna Fertilizers and Chemicals Limited | D3: =_xlfn.XLOOKUP(B3,stock_analysis[Stock],stock_analysis[Sector]) -> Basic Materials | E3: =_xlfn.XLOOKUP($B3,stock_analysis[Stock],stock_analysis[Industry]) -> Agricultural Inputs | F3: =_xlfn.XLOOKUP($B3,stock_analysis[Stock],stock_analysis[Market_Cap_Cr]) -> 262.55053 | G3: =Imputs!$C$2 -> 0.0667 | H3: =Imputs!$C$3 -> 0.0523 | I3: =_xlfn.XLOOKUP($B3,stock_analysis[Stock],stock_analysis[Beta_Daily]) -> 0.42369843 | J3: =_xlfn.XLOOKUP($B3,stock_analysis[Stock],stock_analysis[Beta_Weekly]) -> 0.88594892 | K3: =_xlfn.XLOOKUP($B3,stock_analysis[Stock],stock_analysis[Beta_Monthly]) -> 1.1651509 | L3: =G3+H3*I3 -> 0.088859428 | M3: =J3*H3+G3 -> 0.11303513 | N3: =K3*H3+G3 -> 0.12763739 | O3: =_xlfn.XLOOKUP($B3,stock_analysis[Stock],stock_analysis[Interest_Coverage_Ratio]) -> 189.71151 | P3: {=CHOOSE( _xlfn.IFS(Table2[[#This Row],[Financial Services ]]=TRUE,2,Table2[[#This Row],[FIRM TYPE]]=TRUE,1,Table2[[#This Row],[FIRM TYPE]]=FALSE,3), _xlfn.CHOOSECOLS(_xlfn._xlws.FILTER(Rating1[],(Table2[[#This Row],[Interest Coverage Ratio]]>Rating1[>])*(Table2[[#This Row],[Interest Coverage Ratio]]<Rating1[≤ to])),4), _xlfn.CHOOSECOLS(_xlfn._xlws.FILTER(Rating2[],(Table2[[#This Row],[Interest Coverage Ratio]]>Rating2[greater than])*(Table2[[#This Row],[Interest Coverage Ratio]]<Rating2[≤ to])),4), _xlfn.CHOOSECOLS(_xlfn._xlws.FILTER(Rating3[],(Table2[[#This Row],[Interest Coverage Ratio]]>Rating3[greater than])*(Table2[[#This Row],[Interest Coverage Ratio]]<Rating3[≤ to])),4) )} -> 0.004 | Q3: {=CHOOSE( _xlfn.IFS(Table2[[#This Row],[Financial Services ]]=TRUE,2,Table2[[#This Row],[FIRM TYPE]]=TRUE,1,Table2[[#This Row],[FIRM TYPE]]=FALSE,3), _xlfn.CHOOSECOLS(_xlfn._xlws.FILTER(Rating1[],(Table2[[#This Row],[Interest Coverage Ratio]]>Rating1[>])*(Table2[[#This Row],[Interest Coverage Ratio]]<Rating1[≤ to])),3), _xlfn.CHOOSECOLS(_xlfn._xlws.FILTER(Rating2[],(Table2[[#This Row],[Interest Coverage Ratio]]>Rating2[greater than])*(Table2[[#This Row],[Interest Coverage Ratio]]<Rating2[≤ to])),3), _xlfn.CHOOSECOLS(_xlfn._xlws.FILTER(Rating3[],(Table2[[#This Row],[Interest Coverage Ratio]]>Rating3[greater than])*(Table2[[#This Row],[Interest Coverage Ratio]]<Rating3[≤ to])),3) )} -> Aaa/AAA | R3: =Table2[[#This Row],[Default Spread]]+Table2[[#This Row],[Risk Free Rate]] -> 0.0707 | S3: =_xlfn.XLOOKUP($B3,stock_analysis[Stock],stock_analysis[Market_Cap_Cr]) -> 262.55053 | T3: =_xlfn.XLOOKUP($B3,stock_analysis[Stock],stock_analysis[Total_Debt_Cr]) -> 19.437 | U3: =Table2[[#This Row],[Market Value of Equity]]/(Table2[[#This Row],[Market Value of Equity]]+Table2[[#This Row],[Market Value of Debt]]) -> 0.93107142 | V3: =Table2[[#This Row],[Market Value of Debt]]/(Table2[[#This Row],[Market Value of Equity]]+Table2[[#This Row],[Market Value of Debt]]) -> 0.06892858 | W3: =(Table2[[#This Row],[Cost of Equity (Daily Beta)]]*Table2[[#This Row],[Weight of Equity]])+(Table2[[#This Row],[Cost of Debt]]*Table2[[#This Row],[Weight of Debt]]) -> 0.087607724 | X3: =(Table2[[#This Row],[Cost of Equity (Weekly Beta)]]*Table2[[#This Row],[Weight of Equity]])+(Table2[[#This Row],[Cost of Debt]]*Table2[[#This Row],[Weight of Debt]]) -> 0.11011703 | Y3: =(Table2[[#This Row],[Cost of Equity (Monthly Beta)]]*Table2[[#This Row],[Weight of Equity]])+(Table2[[#This Row],[Cost of Debt]]*Table2[[#This Row],[Weight of Debt]]) -> 0.12371278 | Z3: =IF(Table2[[#This Row],[Sector]]="Financial Services",TRUE,FALSE) -> FALSE | AA3: =IF(Table2[[#This Row],[Market Capitalisation In(Cr)]]>25000,TRUE,FALSE) -> FALSE
B4: OSWALSEEDS | C4: =_xlfn.XLOOKUP(B4,stock_analysis[Stock],stock_analysis[Company_Name]) -> ShreeOswal Seeds And Chemicals Limited | D4: =_xlfn.XLOOKUP(B4,stock_analysis[Stock],stock_analysis[Sector]) -> Basic Materials | E4: =_xlfn.XLOOKUP($B4,stock_analysis[Stock],stock_analysis[Industry]) -> Agricultural Inputs | F4: =_xlfn.XLOOKUP($B4,stock_analysis[Stock],stock_analysis[Market_Cap_Cr]) -> 116.34984 | G4: =Imputs!$C$2 -> 0.0667 | H4: =Imputs!$C$3 -> 0.0523 | I4: =_xlfn.XLOOKUP($B4,stock_analysis[Stock],stock_analysis[Beta_Daily]) -> 0.40441496 | J4: =_xlfn.XLOOKUP($B4,stock_analysis[Stock],stock_analysis[Beta_Weekly]) -> 1.0544635 | K4: =_xlfn.XLOOKUP($B4,stock_analysis[Stock],stock_analysis[Beta_Monthly]) -> -1.0236841 | L4: =G4+H4*I4 -> 0.087850903 | M4: =J4*H4+G4 -> 0.12184844 | N4: =K4*H4+G4 -> 0.01316132 | O4: =_xlfn.XLOOKUP($B4,stock_analysis[Stock],stock_analysis[Interest_Coverage_Ratio]) -> 2.2586428 | P4: {=CHOOSE( _xlfn.IFS(Table2[[#This Row],[Financial Services ]]=TRUE,2,Table2[[#This Row],[FIRM TYPE]]=TRUE,1,Table2[[#This Row],[FIRM TYPE]]=FALSE,3), _xlfn.CHOOSECOLS(_xlfn._xlws.FILTER(Rating1[],(Table2[[#This Row],[Interest Coverage Ratio]]>Rating1[>])*(Table2[[#This Row],[Interest Coverage Ratio]]<Rating1[≤ to])),4), _xlfn.CHOOSECOLS(_xlfn._xlws.FILTER(Rating2[],(Table2[[#This Row],[Interest Coverage Ratio]]>Rating2[greater than])*(Table2[[#This Row],[Interest Coverage Ratio]]<Rating2[≤ to])),4), _xlfn.CHOOSECOLS(_xlfn._xlws.FILTER(Rating3[],(Table2[[#This Row],[Interest Coverage Ratio]]>Rating3[greater than])*(Table2[[#This Row],[Interest Coverage Ratio]]<Rating3[≤ to])),4) )} -> 0.0321 | Q4: {=CHOOSE( _xlfn.IFS(Table2[[#This Row],[Financial Services ]]=TRUE,2,Table2[[#This Row],[FIRM TYPE]]=TRUE,1,Table2[[#This Row],[FIRM TYPE]]=FALSE,3), _xlfn.CHOOSECOLS(_xlfn._xlws.FILTER(Rating1[],(Table2[[#This Row],[Interest Coverage Ratio]]>Rating1[>])*(Table2[[#This Row],[Interest Coverage Ratio]]<Rating1[≤ to])),3), _xlfn.CHOOSECOLS(_xlfn._xlws.FILTER(Rating2[],(Table2[[#This Row],[Interest Coverage Ratio]]>Rating2[greater than])*(Table2[[#This Row],[Interest Coverage Ratio]]<Rating2[≤ to])),3), _xlfn.CHOOSECOLS(_xlfn._xlws.FILTER(Rating3[],(Table2[[#This Row],[Interest Coverage Ratio]]>Rating3[greater than])*(Table2[[#This Row],[Interest Coverage Ratio]]<Rating3[≤ to])),3) )} -> B2/B | R4: =Table2[[#This Row],[Default Spread]]+Table2[[#This Row],[Risk Free Rate]] -> 0.0988 | S4: =_xlfn.XLOOKUP($B4,stock_analysis[Stock],stock_analysis[Market_Cap_Cr]) -> 116.34984 | T4: =_xlfn.XLOOKUP($B4,stock_analysis[Stock],stock_analysis[Total_Debt_Cr]) -> 46.593501 | U4: =Table2[[#This Row],[Market Value of Equity]]/(Table2[[#This Row],[Market Value of Equity]]+Table2[[#This Row],[Market Value of Debt]]) -> 0.7140509 | V4: =Table2[[#This Row],[Market Value of Debt]]/(Table2[[#This Row],[Market Value of Equity]]+Table2[[#This Row],[Market Value of Debt]]) -> 0.2859491 | W4: =(Table2[[#This Row],[Cost of Equity (Daily Beta)]]*Table2[[#This Row],[Weight of Equity]])+(Table2[[#This Row],[Cost of Debt]]*Table2[[#This Row],[Weight of Debt]]) -> 0.090981787 | X4: =(Table2[[#This Row],[Cost of Equity (Weekly Beta)]]*Table2[[#This Row],[Weight of Equity]])+(Table2[[#This Row],[Cost of Debt]]*Table2[[#This Row],[Weight of Debt]]) -> 0.11525776 | Y4: =(Table2[[#This Row],[Cost of Equity (Monthly Beta)]]*Table2[[#This Row],[Weight of Equity]])+(Table2[[#This Row],[Cost of Debt]]*Table2[[#This Row],[Weight of Debt]]) -> 0.037649624 | Z4: =IF(Table2[[#This Row],[Sector]]="Financial Services",TRUE,FALSE) -> FALSE | AA4: =IF(Table2[[#This Row],[Market Capitalisation In(Cr)]]>25000,TRUE,FALSE) -> FALSE
B5: BESTAGRO | C5: =_xlfn.XLOOKUP(B5,stock_analysis[Stock],stock_analysis[Company_Name]) -> Best Agrolife Limited | D5: =_xlfn.XLOOKUP(B5,stock_analysis[Stock],stock_analysis[Sector]) -> Basic Materials | E5: =_xlfn.XLOOKUP($B5,stock_analysis[Stock],stock_analysis[Industry]) -> Agricultural Inputs | F5: =_xlfn.XLOOKUP($B5,stock_analysis[Stock],stock_analysis[Market_Cap_Cr]) -> 550.5919 | G5: =Imputs!$C$2 -> 0.0667 | H5: =Imputs!$C$3 -> 0.0523 | I5: =_xlfn.XLOOKUP($B5,stock_analysis[Stock],stock_analysis[Beta_Daily]) -> 0.43568159 | J5: =_xlfn.XLOOKUP($B5,stock_analysis[Stock],stock_analysis[Beta_Weekly]) -> 0.77127596 | K5: =_xlfn.XLOOKUP($B5,stock_analysis[Stock],stock_analysis[Beta_Monthly]) -> 0.5328715 | L5: =G5+H5*I5 -> 0.089486147 | M5: =J5*H5+G5 -> 0.10703773 | N5: =K5*H5+G5 -> 0.094569179 | O5: =_xlfn.XLOOKUP($B5,stock_analysis[Stock],stock_analysis[Interest_Coverage_Ratio]) -> 2.6000332 | P5: {=CHOOSE( _xlfn.IFS(Table2[[#This Row],[Financial Services ]]=TRUE,2,Table2[[#This Row],[FIRM TYPE]]=TRUE,1,Table2[[#This Row],[FIRM TYPE]]=FALSE,3), _xlfn.CHOOSECOLS(_xlfn._xlws.FILTER(Rating1[],(Table2[[#This Row],[Interest Coverage Ratio]]>Rating1[>])*(Table2[[#This Row],[Interest Coverage Ratio]]<Rating1[≤ to])),4), _xlfn.CHOOSECOLS(_xlfn._xlws.FILTER(Rating2[],(Table2[[#This Row],[Interest Coverage Ratio]]>Rating2[greater than])*(Table2[[#This Row],[Interest Coverage Ratio]]<Rating2[≤ to])),4), _xlfn.CHOOSECOLS(_xlfn._xlws.FILTER(Rating3[],(Table2[[#This Row],[Interest Coverage Ratio]]>Rating3[greater than])*(Table2[[#This Row],[Interest Coverage Ratio]]<Rating3[≤ to])),4) )} -> 0.0275 | Q5: {=CHOOSE( _xlfn.IFS(Table2[[#This Row],[Financial Services ]]=TRUE,2,Table2[[#This Row],[FIRM TYPE]]=TRUE,1,Table2[[#This Row],[FIRM TYPE]]=FALSE,3), _xlfn.CHOOSECOLS(_xlfn._xlws.FILTER(Rating1[],(Table2[[#This Row],[Interest Coverage Ratio]]>Rating1[>])*(Table2[[#This Row],[Interest Coverage Ratio]]<Rating1[≤ to])),3), _xlfn.CHOOSECOLS(_xlfn._xlws.FILTER(Rating2[],(Table2[[#This Row],[Interest Coverage Ratio]]>Rating2[greater than])*(Table2[[#This Row],[Interest Coverage Ratio]]<Rating2[≤ to])),3), _xlfn.CHOOSECOLS(_xlfn._xlws.FILTER(Rating3[],(Table2[[#This Row],[Interest Coverage Ratio]]>Rating3[greater than])*(Table2[[#This Row],[Interest Coverage Ratio]]<Rating3[≤ to])),3) )} -> B1/B+ | R5: =Table2[[#This Row],[Default Spread]]+Table2[[#This Row],[Risk Free Rate]] -> 0.0942 | S5: =_xlfn.XLOOKUP($B5,stock_analysis[Stock],stock_analysis[Market_Cap_Cr]) -> 550.5919 | T5: =_xlfn.XLOOKUP($B5,stock_analysis[Stock],stock_analysis[Total_Debt_Cr]) -> 435.68 | U5: =Table2[[#This Row],[Market Value of Equity]]/(Table2[[#This Row],[Market Value of Equity]]+Table2[[#This Row],[Market Value of Debt]]) -> 0.55825569 | V5: =Table2[[#This Row],[Market Value of Debt]]/(Table2[[#This Row],[Market Value of Equity]]+Table2[[#This Row],[Market Value of Debt]]) -> 0.44174431 | W5: =(Table2[[#This Row],[Cost of Equity (Daily Beta)]]*Table2[[#This Row],[Weight of Equity]])+(Table2[[#This Row],[Cost of Debt]]*Table2[[#This Row],[Weight of Debt]]) -> 0.091568465 | X5: =(Table2[[#This Row],[Cost of Equity (Weekly Beta)]]*Table2[[#This Row],[Weight of Equity]])+(Table2[[#This Row],[Cost of Debt]]*Table2[[#This Row],[Weight of Debt]]) -> 0.10136674 | Y5: =(Table2[[#This Row],[Cost of Equity (Monthly Beta)]]*Table2[[#This Row],[Weight of Equity]])+(Table2[[#This Row],[Cost of Debt]]*Table2[[#This Row],[Weight of Debt]]) -> 0.094406097 | Z5: =IF(Table2[[#This Row],[Sector]]="Financial Services",TRUE,FALSE) -> FALSE | AA5: =IF(Table2[[#This Row],[Market Capitalisation In(Cr)]]>25000,TRUE,FALSE) -> FALSE
B6: BHAGCHEM | C6: =_xlfn.XLOOKUP(B6,stock_analysis[Stock],stock_analysis[Company_Name]) -> Bhagiradha Chemicals & Industries Limited | D6: =_xlfn.XLOOKUP(B6,stock_analysis[Stock],stock_analysis[Sector]) -> Basic Materials | E6: =_xlfn.XLOOKUP($B6,stock_analysis[Stock],stock_analysis[Industry]) -> Agricultural Inputs | F6: =_xlfn.XLOOKUP($B6,stock_analysis[Stock],stock_analysis[Market_Cap_Cr]) -> 2587.8528 | G6: =Imputs!$C$2 -> 0.0667 | H6: =Imputs!$C$3 -> 0.0523 | I6: =_xlfn.XLOOKUP($B6,stock_analysis[Stock],stock_analysis[Beta_Daily]) -> 0.50418825 | J6: =_xlfn.XLOOKUP($B6,stock_analysis[Stock],stock_analysis[Beta_Weekly]) -> 1.0261575 | K6: =_xlfn.XLOOKUP($B6,stock_analysis[Stock],stock_analysis[Beta_Monthly]) -> 1.1118535 | L6: =G6+H6*I6 -> 0.093069045 | M6: =J6*H6+G6 -> 0.12036804 | N6: =K6*H6+G6 -> 0.12484994 | O6: =_xlfn.XLOOKUP($B6,stock_analysis[Stock],stock_analysis[Interest_Coverage_Ratio]) -> 5.9107494 | P6: {=CHOOSE( _xlfn.IFS(Table2[[#This Row],[Financial Services ]]=TRUE,2,Table2[[#This Row],[FIRM TYPE]]=TRUE,1,Table2[[#This Row],[FIRM TYPE]]=FALSE,3), _xlfn.CHOOSECOLS(_xlfn._xlws.FILTER(Rating1[],(Table2[[#This Row],[Interest Coverage Ratio]]>Rating1[>])*(Table2[[#This Row],[Interest Coverage Ratio]]<Rating1[≤ to])),4), _xlfn.CHOOSECOLS(_xlfn._xlws.FILTER(Rating2[],(Table2[[#This Row],[Interest Coverage Ratio]]>Rating2[greater than])*(Table2[[#This Row],[Interest Coverage Ratio]]<Rating2[≤ to])),4), _xlfn.CHOOSECOLS(_xlfn._xlws.FILTER(Rating3[],(Table2[[#This Row],[Interest Coverage Ratio]]>Rating3[greater than])*(Table2[[#This Row],[Interest Coverage Ratio]]<Rating3[≤ to])),4) )} -> 0.0089 | Q6: {=CHOOSE( _xlfn.IFS(Table2[[#This Row],[Financial Services ]]=TRUE,2,Table2[[#This Row],[FIRM TYPE]]=TRUE,1,Table2[[#This Row],[FIRM TYPE]]=FALSE,3), _xlfn.CHOOSECOLS(_xlfn._xlws.FILTER(Rating1[],(Table2[[#This Row],[Interest Coverage Ratio]]>Rating1[>])*(Table2[[#This Row],[Interest Coverage Ratio]]<Rating1[≤ to])),3), _xlfn.CHOOSECOLS(_xlfn._xlws.FILTER(Rating2[],(Table2[[#This Row],[Interest Coverage Ratio]]>Rating2[greater than])*(Table2[[#This Row],[Interest Coverage Ratio]]<Rating2[≤ to])),3), _xlfn.CHOOSECOLS(_xlfn._xlws.FILTER(Rating3[],(Table2[[#This Row],[Interest Coverage Ratio]]>Rating3[greater than])*(Table2[[#This Row],[Interest Coverage Ratio]]<Rating3[≤ to])),3) )} -> A3/A- | R6: =Table2[[#This Row],[Default Spread]]+Table2[[#This Row],[Risk Free Rate]] -> 0.0756 | S6: =_xlfn.XLOOKUP($B6,stock_analysis[Stock],stock_analysis[Market_Cap_Cr]) -> 2587.8528 | T6: =_xlfn.XLOOKUP($B6,stock_analysis[Stock],stock_analysis[Total_Debt_Cr]) -> 188.8293 | U6: =Table2[[#This Row],[Market Value of Equity]]/(Table2[[#This Row],[Market Value of Equity]]+Table2[[#This Row],[Market Value of Debt]]) -> 0.93199463 | V6: =Table2[[#This Row],[Market Value of Debt]]/(Table2[[#This Row],[Market Value of Equity]]+Table2[[#This Row],[Market Value of Debt]]) -> 0.068005372 | W6: =(Table2[[#This Row],[Cost of Equity (Daily Beta)]]*Table2[[#This Row],[Weight of Equity]])+(Table2[[#This Row],[Cost of Debt]]*Table2[[#This Row],[Weight of Debt]]) -> 0.091881056 | X6: =(Table2[[#This Row],[Cost of Equity (Weekly Beta)]]*Table2[[#This Row],[Weight of Equity]])+(Table2[[#This Row],[Cost of Debt]]*Table2[[#This Row],[Weight of Debt]]) -> 0.11732357 | Y6: =(Table2[[#This Row],[Cost of Equity (Monthly Beta)]]*Table2[[#This Row],[Weight of Equity]])+(Table2[[#This Row],[Cost of Debt]]*Table2[[#This Row],[Weight of Debt]]) -> 0.12150068 | Z6: =IF(Table2[[#This Row],[Sector]]="Financial Services",TRUE,FALSE) -> FALSE | AA6: =IF(Table2[[#This Row],[Market Capitalisation In(Cr)]]>25000,TRUE,FALSE) -> FALSE
B7: BAYERCROP | C7: =_xlfn.XLOOKUP(B7,stock_analysis[Stock],stock_analysis[Company_Name]) -> Bayer Cropscience Limited | D7: =_xlfn.XLOOKUP(B7,stock_analysis[Stock],stock_analysis[Sector]) -> Basic Materials | E7: =_xlfn.XLOOKUP($B7,stock_analysis[Stock],stock_analysis[Industry]) -> Agricultural Inputs | F7: =_xlfn.XLOOKUP($B7,stock_analysis[Stock],stock_analysis[Market_Cap_Cr]) -> 20255.257 | G7: =Imputs!$C$2 -> 0.0667 | H7: =Imputs!$C$3 -> 0.0523 | I7: =_xlfn.XLOOKUP($B7,stock_analysis[Stock],stock_analysis[Beta_Daily]) -> 0.50725538 | J7: =_xlfn.XLOOKUP($B7,stock_analysis[Stock],stock_analysis[Beta_Weekly]) -> 1.1368508 | K7: =_xlfn.XLOOKUP($B7,stock_analysis[Stock],stock_analysis[Beta_Monthly]) -> 0.88865631 | L7: =G7+H7*I7 -> 0.093229457 | M7: =J7*H7+G7 -> 0.1261573 | N7: =K7*H7+G7 -> 0.11317673 | O7: =_xlfn.XLOOKUP($B7,stock_analysis[Stock],stock_analysis[Interest_Coverage_Ratio]) -> 42.611765 | P7: {=CHOOSE( _xlfn.IFS(Table2[[#This Row],[Financial Services ]]=TRUE,2,Table2[[#This Row],[FIRM TYPE]]=TRUE,1,Table2[[#This Row],[FIRM TYPE]]=FALSE,3), _xlfn.CHOOSECOLS(_xlfn._xlws.FILTER(Rating1[],(Table2[[#This Row],[Interest Coverage Ratio]]>Rating1[>])*(Table2[[#This Row],[Interest Coverage Ratio]]<Rating1[≤ to])),4), _xlfn.CHOOSECOLS(_xlfn._xlws.FILTER(Rating2[],(Table2[[#This Row],[Interest Coverage Ratio]]>Rating2[greater than])*(Table2[[#This Row],[Interest Coverage Ratio]]<Rating2[≤ to])),4), _xlfn.CHOOSECOLS(_xlfn._xlws.FILTER(Rating3[],(Table2[[#This Row],[Interest Coverage Ratio]]>Rating3[greater than])*(Table2[[#This Row],[Interest Coverage Ratio]]<Rating3[≤ to])),4) )} -> 0.004 | Q7: {=CHOOSE( _xlfn.IFS(Table2[[#This Row],[Financial Services ]]=TRUE,2,Table2[[#This Row],[FIRM TYPE]]=TRUE,1,Table2[[#This Row],[FIRM TYPE]]=FALSE,3), _xlfn.CHOOSECOLS(_xlfn._xlws.FILTER(Rating1[],(Table2[[#This Row],[Interest Coverage Ratio]]>Rating1[>])*(Table2[[#This Row],[Interest Coverage Ratio]]<Rating1[≤ to])),3), _xlfn.CHOOSECOLS(_xlfn._xlws.FILTER(Rating2[],(Table2[[#This Row],[Interest Coverage Ratio]]>Rating2[greater than])*(Table2[[#This Row],[Interest Coverage Ratio]]<Rating2[≤ to])),3), _xlfn.CHOOSECOLS(_xlfn._xlws.FILTER(Rating3[],(Table2[[#This Row],[Interest Coverage Ratio]]>Rating3[greater than])*(Table2[[#This Row],[Interest Coverage Ratio]]<Rating3[≤ to])),3) )} -> Aaa/AAA | R7: =Table2[[#This Row],[Default Spread]]+Table2[[#This Row],[Risk Free Rate]] -> 0.0707 | S7: =_xlfn.XLOOKUP($B7,stock_analysis[Stock],stock_analysis[Market_Cap_Cr]) -> 20255.257 | T7: =_xlfn.XLOOKUP($B7,stock_analysis[Stock],stock_analysis[Total_Debt_Cr]) -> 102 | U7: =Table2[[#This Row],[Market Value of Equity]]/(Table2[[#This Row],[Market Value of Equity]]+Table2[[#This Row],[Market Value of Debt]]) -> 0.9949895 | V7: =Table2[[#This Row],[Market Value of Debt]]/(Table2[[#This Row],[Market Value of Equity]]+Table2[[#This Row],[Market Value of Debt]]) -> 0.0050104981 | W7: =(Table2[[#This Row],[Cost of Equity (Daily Beta)]]*Table2[[#This Row],[Weight of Equity]])+(Table2[[#This Row],[Cost of Debt]]*Table2[[#This Row],[Weight of Debt]]) -> 0.093116573 | X7: =(Table2[[#This Row],[Cost of Equity (Weekly Beta)]]*Table2[[#This Row],[Weight of Equity]])+(Table2[[#This Row],[Cost of Debt]]*Table2[[#This Row],[Weight of Debt]]) -> 0.12587943 | Y7: =(Table2[[#This Row],[Cost of Equity (Monthly Beta)]]*Table2[[#This Row],[Weight of Equity]])+(Table2[[#This Row],[Cost of Debt]]*Table2[[#This Row],[Weight of Debt]]) -> 0.1129639 | Z7: =IF(Table2[[#This Row],[Sector]]="Financial Services",TRUE,FALSE) -> FALSE | AA7: =IF(Table2[[#This Row],[Market Capitalisation In(Cr)]]>25000,TRUE,FALSE) -> FALSE
B8: INSECTICID | C8: =_xlfn.XLOOKUP(B8,stock_analysis[Stock],stock_analysis[Company_Name]) -> Insecticides (India) Limited | D8: =_xlfn.XLOOKUP(B8,stock_analysis[Stock],stock_analysis[Sector]) -> Basic Materials | E8: =_xlfn.XLOOKUP($B8,stock_analysis[Stock],stock_analysis[Industry]) -> Agricultural Inputs | F8: =_xlfn.XLOOKUP($B8,stock_analysis[Stock],stock_analysis[Market_Cap_Cr]) -> 1776.8593 | G8: =Imputs!$C$2 -> 0.0667 | H8: =Imputs!$C$3 -> 0.0523 | I8: =_xlfn.XLOOKUP($B8,stock_analysis[Stock],stock_analysis[Beta_Daily]) -> 0.6201922 | J8: =_xlfn.XLOOKUP($B8,stock_analysis[Stock],stock_analysis[Beta_Weekly]) -> 1.2702471 | K8: =_xlfn.XLOOKUP($B8,stock_analysis[Stock],stock_analysis[Beta_Monthly]) -> 1.0892812 | L8: =G8+H8*I8 -> 0.099136052 | M8: =J8*H8+G8 -> 0.13313392 | N8: =K8*H8+G8 -> 0.12366941 | O8: =_xlfn.XLOOKUP($B8,stock_analysis[Stock],stock_analysis[Interest_Coverage_Ratio]) -> 40.55867 | P8: {=CHOOSE( _xlfn.IFS(Table2[[#This Row],[Financial Services ]]=TRUE,2,Table2[[#This Row],[FIRM TYPE]]=TRUE,1,Table2[[#This Row],[FIRM TYPE]]=FALSE,3), _xlfn.CHOOSECOLS(_xlfn._xlws.FILTER(Rating1[],(Table2[[#This Row],[Interest Coverage Ratio]]>Rating1[>])*(Table2[[#This Row],[Interest Coverage Ratio]]<Rating1[≤ to])),4), _xlfn.CHOOSECOLS(_xlfn._xlws.FILTER(Rating2[],(Table2[[#This Row],[Interest Coverage Ratio]]>Rating2[greater than])*(Table2[[#This Row],[Interest Coverage Ratio]]<Rating2[≤ to])),4), _xlfn.CHOOSECOLS(_xlfn._xlws.FILTER(Rating3[],(Table2[[#This Row],[Interest Coverage Ratio]]>Rating3[greater than])*(Table2[[#This Row],[Interest Coverage Ratio]]<Rating3[≤ to])),4) )} -> 0.004 | Q8: {=CHOOSE( _xlfn.IFS(Table2[[#This Row],[Financial Services ]]=TRUE,2,Table2[[#This Row],[FIRM TYPE]]=TRUE,1,Table2[[#This Row],[FIRM TYPE]]=FALSE,3), _xlfn.CHOOSECOLS(_xlfn._xlws.FILTER(Rating1[],(Table2[[#This Row],[Interest Coverage Ratio]]>Rating1[>])*(Table2[[#This Row],[Interest Coverage Ratio]]<Rating1[≤ to])),3), _xlfn.CHOOSECOLS(_xlfn._xlws.FILTER(Rating2[],(Table2[[#This Row],[Interest Coverage Ratio]]>Rating2[greater than])*(Table2[[#This Row],[Interest Coverage Ratio]]<Rating2[≤ to])),3), _xlfn.CHOOSECOLS(_xlfn._xlws.FILTER(Rating3[],(Table2[[#This Row],[Interest Coverage Ratio]]>Rating3[greater than])*(Table2[[#This Row],[Interest Coverage Ratio]]<Rating3[≤ to])),3) )} -> Aaa/AAA | R8: =Table2[[#This Row],[Default Spread]]+Table2[[#This Row],[Risk Free Rate]] -> 0.0707 | S8: =_xlfn.XLOOKUP($B8,stock_analysis[Stock],stock_analysis[Market_Cap_Cr]) -> 1776.8593 | T8: =_xlfn.XLOOKUP($B8,stock_analysis[Stock],stock_analysis[Total_Debt_Cr]) -> 246.44539 | U8: =Table2[[#This Row],[Market Value of Equity]]/(Table2[[#This Row],[Market Value of Equity]]+Table2[[#This Row],[Market Value of Debt]]) -> 0.8781966 | V8: =Table2[[#This Row],[Market Value of Debt]]/(Table2[[#This Row],[Market Value of Equity]]+Table2[[#This Row],[Market Value of Debt]]) -> 0.1218034 | W8: =(Table2[[#This Row],[Cost of Equity (Daily Beta)]]*Table2[[#This Row],[Weight of Equity]])+(Table2[[#This Row],[Cost of Debt]]*Table2[[#This Row],[Weight of Debt]]) -> 0.095672444 | X8: =(Table2[[#This Row],[Cost of Equity (Weekly Beta)]]*Table2[[#This Row],[Weight of Equity]])+(Table2[[#This Row],[Cost of Debt]]*Table2[[#This Row],[Weight of Debt]]) -> 0.12552926 | Y8: =(Table2[[#This Row],[Cost of Equity (Monthly Beta)]]*Table2[[#This Row],[Weight of Equity]])+(Table2[[#This Row],[Cost of Debt]]*Table2[[#This Row],[Weight of Debt]]) -> 0.11721755 | Z8: =IF(Table2[[#This Row],[Sector]]="Financial Services",TRUE,FALSE) -> FALSE | AA8: =IF(Table2[[#This Row],[Market Capitalisation In(Cr)]]>25000,TRUE,FALSE) -> FALSE
B9: SIKKO | C9: =_xlfn.XLOOKUP(B9,stock_analysis[Stock],stock_analysis[Company_Name]) -> Sikko Industries Limited | D9: =_xlfn.XLOOKUP(B9,stock_analysis[Stock],stock_analysis[Sector]) -> Basic Materials | E9: =_xlfn.XLOOKUP($B9,stock_analysis[Stock],stock_analysis[Industry]) -> Agricultural Inputs | F9: =_xlfn.XLOOKUP($B9,stock_analysis[Stock],stock_analysis[Market_Cap_Cr]) -> 196.56 | G9: =Imputs!$C$2 -> 0.0667 | H9: =Imputs!$C$3 -> 0.0523 | I9: =_xlfn.XLOOKUP($B9,stock_analysis[Stock],stock_analysis[Beta_Daily]) -> 0.63903525 | J9: =_xlfn.XLOOKUP($B9,stock_analysis[Stock],stock_analysis[Beta_Weekly]) -> 1.3034265 | K9: =_xlfn.XLOOKUP($B9,stock_analysis[Stock],stock_analysis[Beta_Monthly]) -> 1.9895812 | L9: =G9+H9*I9 -> 0.10012154 | M9: =J9*H9+G9 -> 0.13486921 | N9: =K9*H9+G9 -> 0.1707551 | O9: =_xlfn.XLOOKUP($B9,stock_analysis[Stock],stock_analysis[Interest_Coverage_Ratio]) -> 16.921879 | P9: {=CHOOSE( _xlfn.IFS(Table2[[#This Row],[Financial Services ]]=TRUE,2,Table2[[#This Row],[FIRM TYPE]]=TRUE,1,Table2[[#This Row],[FIRM TYPE]]=FALSE,3), _xlfn.CHOOSECOLS(_xlfn._xlws.FILTER(Rating1[],(Table2[[#This Row],[Interest Coverage Ratio]]>Rating1[>])*(Table2[[#This Row],[Interest Coverage Ratio]]<Rating1[≤ to])),4), _xlfn.CHOOSECOLS(_xlfn._xlws.FILTER(Rating2[],(Table2[[#This Row],[Interest Coverage Ratio]]>Rating2[greater than])*(Table2[[#This Row],[Interest Coverage Ratio]]<Rating2[≤ to])),4), _xlfn.CHOOSECOLS(_xlfn._xlws.FILTER(Rating3[],(Table2[[#This Row],[Interest Coverage Ratio]]>Rating3[greater than])*(Table2[[#This Row],[Interest Coverage Ratio]]<Rating3[≤ to])),4) )} -> 0.004 | Q9: {=CHOOSE( _xlfn.IFS(Table2[[#This Row],[Financial Services ]]=TRUE,2,Table2[[#This Row],[FIRM TYPE]]=TRUE,1,Table2[[#This Row],[FIRM TYPE]]=FALSE,3), _xlfn.CHOOSECOLS(_xlfn._xlws.FILTER(Rating1[],(Table2[[#This Row],[Interest Coverage Ratio]]>Rating1[>])*(Table2[[#This Row],[Interest Coverage Ratio]]<Rating1[≤ to])),3), _xlfn.CHOOSECOLS(_xlfn._xlws.FILTER(Rating2[],(Table2[[#This Row],[Interest Coverage Ratio]]>Rating2[greater than])*(Table2[[#This Row],[Interest Coverage Ratio]]<Rating2[≤ to])),3), _xlfn.CHOOSECOLS(_xlfn._xlws.FILTER(Rating3[],(Table2[[#This Row],[Interest Coverage Ratio]]>Rating3[greater than])*(Table2[[#This Row],[Interest Coverage Ratio]]<Rating3[≤ to])),3) )} -> Aaa/AAA | R9: =Table2[[#This Row],[Default Spread]]+Table2[[#This Row],[Risk Free Rate]] -> 0.0707 | S9: =_xlfn.XLOOKUP($B9,stock_analysis[Stock],stock_analysis[Market_Cap_Cr]) -> 196.56 | T9: =_xlfn.XLOOKUP($B9,stock_analysis[Stock],stock_analysis[Total_Debt_Cr]) -> 12.2905 | U9: =Table2[[#This Row],[Market Value of Equity]]/(Table2[[#This Row],[Market Value of Equity]]+Table2[[#This Row],[Market Value of Debt]]) -> 0.94115169 | V9: =Table2[[#This Row],[Market Value of Debt]]/(Table2[[#This Row],[Market Value of Equity]]+Table2[[#This Row],[Market Value of Debt]]) -> 0.058848315 | W9: =(Table2[[#This Row],[Cost of Equity (Daily Beta)]]*Table2[[#This Row],[Weight of Equity]])+(Table2[[#This Row],[Cost of Debt]]*Table2[[#This Row],[Weight of Debt]]) -> 0.098390135 | X9: =(Table2[[#This Row],[Cost of Equity (Weekly Beta)]]*Table2[[#This Row],[Weight of Equity]])+(Table2[[#This Row],[Cost of Debt]]*Table2[[#This Row],[Weight of Debt]]) -> 0.13109296 | Y9: =(Table2[[#This Row],[Cost of Equity (Monthly Beta)]]*Table2[[#This Row],[Weight of Equity]])+(Table2[[#This Row],[Cost of Debt]]*Table2[[#This Row],[Weight of Debt]]) -> 0.16486702 | Z9: =IF(Table2[[#This Row],[Sector]]="Financial Services",TRUE,FALSE) -> FALSE | AA9: =IF(Table2[[#This Row],[Market Capitalisation In(Cr)]]>25000,TRUE,FALSE) -> FALSE
B10: DHARMAJ | C10: =_xlfn.XLOOKUP(B10,stock_analysis[Stock],stock_analysis[Company_Name]) -> Dharmaj Crop Guard Limited | D10: =_xlfn.XLOOKUP(B10,stock_analysis[Stock],stock_analysis[Sector]) -> Basic Materials | E10: =_xlfn.XLOOKUP($B10,stock_analysis[Stock],stock_analysis[Industry]) -> Agricultural Inputs | F10: =_xlfn.XLOOKUP($B10,stock_analysis[Stock],stock_analysis[Market_Cap_Cr]) -> 812.45317 | G10: =Imputs!$C$2 -> 0.0667 | H10: =Imputs!$C$3 -> 0.0523 | I10: =_xlfn.XLOOKUP($B10,stock_analysis[Stock],stock_analysis[Beta_Daily]) -> 0.71048324 | J10: =_xlfn.XLOOKUP($B10,stock_analysis[Stock],stock_analysis[Beta_Weekly]) -> 1.1768834 | K10: =_xlfn.XLOOKUP($B10,stock_analysis[Stock],stock_analysis[Beta_Monthly]) -> 1.0270976 | L10: =G10+H10*I10 -> 0.10385827 | M10: =J10*H10+G10 -> 0.128251 | N10: =K10*H10+G10 -> 0.1204172 | O10: =_xlfn.XLOOKUP($B10,stock_analysis[Stock],stock_analysis[Interest_Coverage_Ratio]) -> 5.1574596 | P10: {=CHOOSE( _xlfn.IFS(Table2[[#This Row],[Financial Services ]]=TRUE,2,Table2[[#This Row],[FIRM TYPE]]=TRUE,1,Table2[[#This Row],[FIRM TYPE]]=FALSE,3), _xlfn.CHOOSECOLS(_xlfn._xlws.FILTER(Rating1[],(Table2[[#This Row],[Interest Coverage Ratio]]>Rating1[>])*(Table2[[#This Row],[Interest Coverage Ratio]]<Rating1[≤ to])),4), _xlfn.CHOOSECOLS(_xlfn._xlws.FILTER(Rating2[],(Table2[[#This Row],[Interest Coverage Ratio]]>Rating2[greater than])*(Table2[[#This Row],[Interest Coverage Ratio]]<Rating2[≤ to])),4), _xlfn.CHOOSECOLS(_xlfn._xlws.FILTER(Rating3[],(Table2[[#This Row],[Interest Coverage Ratio]]>Rating3[greater than])*(Table2[[#This Row],[Interest Coverage Ratio]]<Rating3[≤ to])),4) )} -> 0.0089 | Q10: {=CHOOSE( _xlfn.IFS(Table2[[#This Row],[Financial Services ]]=TRUE,2,Table2[[#This Row],[FIRM TYPE]]=TRUE,1,Table2[[#This Row],[FIRM TYPE]]=FALSE,3), _xlfn.CHOOSECOLS(_xlfn._xlws.FILTER(Rating1[],(Table2[[#This Row],[Interest Coverage Ratio]]>Rating1[>])*(Table2[[#This Row],[Interest Coverage Ratio]]<Rating1[≤ to])),3), _xlfn.CHOOSECOLS(_xlfn._xlws.FILTER(Rating2[],(Table2[[#This Row],[Interest Coverage Ratio]]>Rating2[greater than])*(Table2[[#This Row],[Interest Coverage Ratio]]<Rating2[≤ to])),3), _xlfn.CHOOSECOLS(_xlfn._xlws.FILTER(Rating3[],(Table2[[#This Row],[Interest Coverage Ratio]]>Rating3[greater than])*(Table2[[#This Row],[Interest Coverage Ratio]]<Rating3[≤ to])),3) )} -> A3/A- | R10: =Table2[[#This Row],[Default Spread]]+Table2[[#This Row],[Risk Free Rate]] -> 0.0756 | S10: =_xlfn.XLOOKUP($B10,stock_analysis[Stock],stock_analysis[Market_Cap_Cr]) -> 812.45317 | T10: =_xlfn.XLOOKUP($B10,stock_analysis[Stock],stock_analysis[Total_Debt_Cr]) -> 138.875 | U10: =Table2[[#This Row],[Market Value of Equity]]/(Table2[[#This Row],[Market Value of Equity]]+Table2[[#This Row],[Market Value of Debt]]) -> 0.85401988 | V10: =Table2[[#This Row],[Market Value of Debt]]/(Table2[[#This Row],[Market Value of Equity]]+Table2[[#This Row],[Market Value of Debt]]) -> 0.14598012 | W10: =(Table2[[#This Row],[Cost of Equity (Daily Beta)]]*Table2[[#This Row],[Weight of Equity]])+(Table2[[#This Row],[Cost of Debt]]*Table2[[#This Row],[Weight of Debt]]) -> 0.099733128 | X10: =(Table2[[#This Row],[Cost of Equity (Weekly Beta)]]*Table2[[#This Row],[Weight of Equity]])+(Table2[[#This Row],[Cost of Debt]]*Table2[[#This Row],[Weight of Debt]]) -> 0.120565 | Y10: =(Table2[[#This Row],[Cost of Equity (Monthly Beta)]]*Table2[[#This Row],[Weight of Equity]])+(Table2[[#This Row],[Cost of Debt]]*Table2[[#This Row],[Weight of Debt]]) -> 0.11387478 | Z10: =IF(Table2[[#This Row],[Sector]]="Financial Services",TRUE,FALSE) -> FALSE | AA10: =IF(Table2[[#This Row],[Market Capitalisation In(Cr)]]>25000,TRUE,FALSE) -> FALSE
B11: INDOUS | C11: =_xlfn.XLOOKUP(B11,stock_analysis[Stock],stock_analysis[Company_Name]) -> Indo Us Biotech Limited | D11: =_xlfn.XLOOKUP(B11,stock_analysis[Stock],stock_analysis[Sector]) -> Basic Materials | E11: =_xlfn.XLOOKUP($B11,stock_analysis[Stock],stock_analysis[Industry]) -> Agricultural Inputs | F11: =_xlfn.XLOOKUP($B11,stock_analysis[Stock],stock_analysis[Market_Cap_Cr]) -> 276.40061 | G11: =Imputs!$C$2 -> 0.0667 | H11: =Imputs!$C$3 -> 0.0523 | I11: =_xlfn.XLOOKUP($B11,stock_analysis[Stock],stock_analysis[Beta_Daily]) -> 0.69794506 | J11: =_xlfn.XLOOKUP($B11,stock_analysis[Stock],stock_analysis[Beta_Weekly]) -> 1.1978305 | K11: =_xlfn.XLOOKUP($B11,stock_analysis[Stock],stock_analysis[Beta_Monthly]) -> -0.67415215 | L11: =G11+H11*I11 -> 0.10320253 | M11: =J11*H11+G11 -> 0.12934653 | N11: =K11*H11+G11 -> 0.031441843 | O11: =_xlfn.XLOOKUP($B11,stock_analysis[Stock],stock_analysis[Interest_Coverage_Ratio]) -> 12.510954 | P11: {=CHOOSE( _xlfn.IFS(Table2[[#This Row],[Financial Services ]]=TRUE,2,Table2[[#This Row],[FIRM TYPE]]=TRUE,1,Table2[[#This Row],[FIRM TYPE]]=FALSE,3), _xlfn.CHOOSECOLS(_xlfn._xlws.FILTER(Rating1[],(Table2[[#This Row],[Interest Coverage Ratio]]>Rating1[>])*(Table2[[#This Row],[Interest Coverage Ratio]]<Rating1[≤ to])),4), _xlfn.CHOOSECOLS(_xlfn._xlws.FILTER(Rating2[],(Table2[[#This Row],[Interest Coverage Ratio]]>Rating2[greater than])*(Table2[[#This Row],[Interest Coverage Ratio]]<Rating2[≤ to])),4), _xlfn.CHOOSECOLS(_xlfn._xlws.FILTER(Rating3[],(Table2[[#This Row],[Interest Coverage Ratio]]>Rating3[greater than])*(Table2[[#This Row],[Interest Coverage Ratio]]<Rating3[≤ to])),4) )} -> 0.004 | Q11: {=CHOOSE( _xlfn.IFS(Table2[[#This Row],[Financial Services ]]=TRUE,2,Table2[[#This Row],[FIRM TYPE]]=TRUE,1,Table2[[#This Row],[FIRM TYPE]]=FALSE,3), _xlfn.CHOOSECOLS(_xlfn._xlws.FILTER(Rating1[],(Table2[[#This Row],[Interest Coverage Ratio]]>Rating1[>])*(Table2[[#This Row],[Interest Coverage Ratio]]<Rating1[≤ to])),3), _xlfn.CHOOSECOLS(_xlfn._xlws.FILTER(Rating2[],(Table2[[#This Row],[Interest Coverage Ratio]]>Rating2[greater than])*(Table2[[#This Row],[Interest Coverage Ratio]]<Rating2[≤ to])),3), _xlfn.CHOOSECOLS(_xlfn._xlws.FILTER(Rating3[],(Table2[[#This Row],[Interest Coverage Ratio]]>Rating3[greater than])*(Table2[[#This Row],[Interest Coverage Ratio]]<Rating3[≤ to])),3) )} -> Aaa/AAA | R11: =Table2[[#This Row],[Default Spread]]+Table2[[#This Row],[Risk Free Rate]] -> 0.0707 | S11: =_xlfn.XLOOKUP($B11,stock_analysis[Stock],stock_analysis[Market_Cap_Cr]) -> 276.40061 | T11: =_xlfn.XLOOKUP($B11,stock_analysis[Stock],stock_analysis[Total_Debt_Cr]) -> 27.643398 | U11: =Table2[[#This Row],[Market Value of Equity]]/(Table2[[#This Row],[Market Value of Equity]]+Table2[[#This Row],[Market Value of Debt]]) -> 0.90908093 | V11: =Table2[[#This Row],[Market Value of Debt]]/(Table2[[#This Row],[Market Value of Equity]]+Table2[[#This Row],[Market Value of Debt]]) -> 0.090919068 | W11: =(Table2[[#This Row],[Cost of Equity (Daily Beta)]]*Table2[[#This Row],[Weight of Equity]])+(Table2[[#This Row],[Cost of Debt]]*Table2[[#This Row],[Weight of Debt]]) -> 0.10024743 | X11: =(Table2[[#This Row],[Cost of Equity (Weekly Beta)]]*Table2[[#This Row],[Weight of Equity]])+(Table2[[#This Row],[Cost of Debt]]*Table2[[#This Row],[Weight of Debt]]) -> 0.12401445 | Y11: =(Table2[[#This Row],[Cost of Equity (Monthly Beta)]]*Table2[[#This Row],[Weight of Equity]])+(Table2[[#This Row],[Cost of Debt]]*Table2[[#This Row],[Weight of Debt]]) -> 0.035011158 | Z11: =IF(Table2[[#This Row],[Sector]]="Financial Services",TRUE,FALSE) -> FALSE | AA11: =IF(Table2[[#This Row],[Market Capitalisation In(Cr)]]>25000,TRUE,FALSE) -> FALSE
B12: MBAPL | C12: =_xlfn.XLOOKUP(B12,stock_analysis[Stock],stock_analysis[Company_Name]) -> Madhya Bharat Agro Products Limited | D12: =_xlfn.XLOOKUP(B12,stock_analysis[Stock],stock_analysis[Sector]) -> Basic Materials | E12: =_xlfn.XLOOKUP($B12,stock_analysis[Stock],stock_analysis[Industry]) -> Agricultural Inputs | F12: =_xlfn.XLOOKUP($B12,stock_analysis[Stock],stock_analysis[Market_Cap_Cr]) -> 4058.0039 | G12: =Imputs!$C$2 -> 0.0667 | H12: =Imputs!$C$3 -> 0.0523 | I12: =_xlfn.XLOOKUP($B12,stock_analysis[Stock],stock_analysis[Beta_Daily]) -> 0.70754567 | J12: =_xlfn.XLOOKUP($B12,stock_analysis[Stock],stock_analysis[Beta_Weekly]) -> 0.54003016 | K12: =_xlfn.XLOOKUP($B12,stock_analysis[Stock],stock_analysis[Beta_Monthly]) -> 0.099410438 | L12: =G12+H12*I12 -> 0.10370464 | M12: =J12*H12+G12 -> 0.094943577 | N12: =K12*H12+G12 -> 0.071899166 | O12: =_xlfn.XLOOKUP($B12,stock_analysis[Stock],stock_analysis[Interest_Coverage_Ratio]) -> 4.5335801 | P12: {=CHOOSE( _xlfn.IFS(Table2[[#This Row],[Financial Services ]]=TRUE,2,Table2[[#This Row],[FIRM TYPE]]=TRUE,1,Table2[[#This Row],[FIRM TYPE]]=FALSE,3), _xlfn.CHOOSECOLS(_xlfn._xlws.FILTER(Rating1[],(Table2[[#This Row],[Interest Coverage Ratio]]>Rating1[>])*(Table2[[#This Row],[Interest Coverage Ratio]]<Rating1[≤ to])),4), _xlfn.CHOOSECOLS(_xlfn._xlws.FILTER(Rating2[],(Table2[[#This Row],[Interest Coverage Ratio]]>Rating2[greater than])*(Table2[[#This Row],[Interest Coverage Ratio]]<Rating2[≤ to])),4), _xlfn.CHOOSECOLS(_xlfn._xlws.FILTER(Rating3[],(Table2[[#This Row],[Interest Coverage Ratio]]>Rating3[greater than])*(Table2[[#This Row],[Interest Coverage Ratio]]<Rating3[≤ to])),4) )} -> 0.0089 | Q12: {=CHOOSE( _xlfn.IFS(Table2[[#This Row],[Financial Services ]]=TRUE,2,Table2[[#This Row],[FIRM TYPE]]=TRUE,1,Table2[[#This Row],[FIRM TYPE]]=FALSE,3), _xlfn.CHOOSECOLS(_xlfn._xlws.FILTER(Rating1[],(Table2[[#This Row],[Interest Coverage Ratio]]>Rating1[>])*(Table2[[#This Row],[Interest Coverage Ratio]]<Rating1[≤ to])),3), _xlfn.CHOOSECOLS(_xlfn._xlws.FILTER(Rating2[],(Table2[[#This Row],[Interest Coverage Ratio]]>Rating2[greater than])*(Table2[[#This Row],[Interest Coverage Ratio]]<Rating2[≤ to])),3), _xlfn.CHOOSECOLS(_xlfn._xlws.FILTER(Rating3[],(Table2[[#This Row],[Interest Coverage Ratio]]>Rating3[greater than])*(Table2[[#This Row],[Interest Coverage Ratio]]<Rating3[≤ to])),3) )} -> A3/A- | R12: =Table2[[#This Row],[Default Spread]]+Table2[[#This Row],[Risk Free Rate]] -> 0.0756 | S12: =_xlfn.XLOOKUP($B12,stock_analysis[Stock],stock_analysis[Market_Cap_Cr]) -> 4058.0039 | T12: =_xlfn.XLOOKUP($B12,stock_analysis[Stock],stock_analysis[Total_Debt_Cr]) -> 312.21571 | U12: =Table2[[#This Row],[Market Value of Equity]]/(Table2[[#This Row],[Market Value of Equity]]+Table2[[#This Row],[Market Value of Debt]]) -> 0.92855835 | V12: =Table2[[#This Row],[Market Value of Debt]]/(Table2[[#This Row],[Market Value of Equity]]+Table2[[#This Row],[Market Value of Debt]]) -> 0.071441652 | W12: =(Table2[[#This Row],[Cost of Equity (Daily Beta)]]*Table2[[#This Row],[Weight of Equity]])+(Table2[[#This Row],[Cost of Debt]]*Table2[[#This Row],[Weight of Debt]]) -> 0.1016968 | X12: =(Table2[[#This Row],[Cost of Equity (Weekly Beta)]]*Table2[[#This Row],[Weight of Equity]])+(Table2[[#This Row],[Cost of Debt]]*Table2[[#This Row],[Weight of Debt]]) -> 0.09356164 | Y12: =(Table2[[#This Row],[Cost of Equity (Monthly Beta)]]*Table2[[#This Row],[Weight of Equity]])+(Table2[[#This Row],[Cost of Debt]]*Table2[[#This Row],[Weight of Debt]]) -> 0.07216356 | Z12: =IF(Table2[[#This Row],[Sector]]="Financial Services",TRUE,FALSE) -> FALSE | AA12: =IF(Table2[[#This Row],[Market Capitalisation In(Cr)]]>25000,TRUE,FALSE) -> FALSE
B13: NATHBIOGEN | C13: =_xlfn.XLOOKUP(B13,stock_analysis[Stock],stock_analysis[Company_Name]) -> Nath Bio-Genes (India) Limited | D13: =_xlfn.XLOOKUP(B13,stock_analysis[Stock],stock_analysis[Sector]) -> Basic Materials | E13: =_xlfn.XLOOKUP($B13,stock_analysis[Stock],stock_analysis[Industry]) -> Agricultural Inputs | F13: =_xlfn.XLOOKUP($B13,stock_analysis[Stock],stock_analysis[Market_Cap_Cr]) -> 272.13507 | G13: =Imputs!$C$2 -> 0.0667 | H13: =Imputs!$C$3 -> 0.0523 | I13: =_xlfn.XLOOKUP($B13,stock_analysis[Stock],stock_analysis[Beta_Daily]) -> 0.99060073 | J13: =_xlfn.XLOOKUP($B13,stock_analysis[Stock],stock_analysis[Beta_Weekly]) -> 1.4398622 | K13: =_xlfn.XLOOKUP($B13,stock_analysis[Stock],stock_analysis[Beta_Monthly]) -> 1.3740203 | L13: =G13+H13*I13 -> 0.11850842 | M13: =J13*H13+G13 -> 0.14200479 | N13: =K13*H13+G13 -> 0.13856126 | O13: =_xlfn.XLOOKUP($B13,stock_analysis[Stock],stock_analysis[Interest_Coverage_Ratio]) -> 5.0996 | P13: {=CHOOSE( _xlfn.IFS(Table2[[#This Row],[Financial Services ]]=TRUE,2,Table2[[#This Row],[FIRM TYPE]]=TRUE,1,Table2[[#This Row],[FIRM TYPE]]=FALSE,3), _xlfn.CHOOSECOLS(_xlfn._xlws.FILTER(Rating1[],(Table2[[#This Row],[Interest Coverage Ratio]]>Rating1[>])*(Table2[[#This Row],[Interest Coverage Ratio]]<Rating1[≤ to])),4), _xlfn.CHOOSECOLS(_xlfn._xlws.FILTER(Rating2[],(Table2[[#This Row],[Interest Coverage Ratio]]>Rating2[greater than])*(Table2[[#This Row],[Interest Coverage Ratio]]<Rating2[≤ to])),4), _xlfn.CHOOSECOLS(_xlfn._xlws.FILTER(Rating3[],(Table2[[#This Row],[Interest Coverage Ratio]]>Rating3[greater than])*(Table2[[#This Row],[Interest Coverage Ratio]]<Rating3[≤ to])),4) )} -> 0.0089 | Q13: {=CHOOSE( _xlfn.IFS(Table2[[#This Row],[Financial Services ]]=TRUE,2,Table2[[#This Row],[FIRM TYPE]]=TRUE,1,Table2[[#This Row],[FIRM TYPE]]=FALSE,3), _xlfn.CHOOSECOLS(_xlfn._xlws.FILTER(Rating1[],(Table2[[#This Row],[Interest Coverage Ratio]]>Rating1[>])*(Table2[[#This Row],[Interest Coverage Ratio]]<Rating1[≤ to])),3), _xlfn.CHOOSECOLS(_xlfn._xlws.FILTER(Rating2[],(Table2[[#This Row],[Interest Coverage Ratio]]>Rating2[greater than])*(Table2[[#This Row],[Interest Coverage Ratio]]<Rating2[≤ to])),3), _xlfn.CHOOSECOLS(_xlfn._xlws.FILTER(Rating3[],(Table2[[#This Row],[Interest Coverage Ratio]]>Rating3[greater than])*(Table2[[#This Row],[Interest Coverage Ratio]]<Rating3[≤ to])),3) )} -> A3/A- | R13: =Table2[[#This Row],[Default Spread]]+Table2[[#This Row],[Risk Free Rate]] -> 0.0756 | S13: =_xlfn.XLOOKUP($B13,stock_analysis[Stock],stock_analysis[Market_Cap_Cr]) -> 272.13507 | T13: =_xlfn.XLOOKUP($B13,stock_analysis[Stock],stock_analysis[Total_Debt_Cr]) -> 154.8288 | U13: =Table2[[#This Row],[Market Value of Equity]]/(Table2[[#This Row],[Market Value of Equity]]+Table2[[#This Row],[Market Value of Debt]]) -> 0.63737259 | V13: =Table2[[#This Row],[Market Value of Debt]]/(Table2[[#This Row],[Market Value of Equity]]+Table2[[#This Row],[Market Value of Debt]]) -> 0.36262741 | W13: =(Table2[[#This Row],[Cost of Equity (Daily Beta)]]*Table2[[#This Row],[Weight of Equity]])+(Table2[[#This Row],[Cost of Debt]]*Table2[[#This Row],[Weight of Debt]]) -> 0.10294865 | X13: =(Table2[[#This Row],[Cost of Equity (Weekly Beta)]]*Table2[[#This Row],[Weight of Equity]])+(Table2[[#This Row],[Cost of Debt]]*Table2[[#This Row],[Weight of Debt]]) -> 0.1179246 | Y13: =(Table2[[#This Row],[Cost of Equity (Monthly Beta)]]*Table2[[#This Row],[Weight of Equity]])+(Table2[[#This Row],[Cost of Debt]]*Table2[[#This Row],[Weight of Debt]]) -> 0.11572978 | Z13: =IF(Table2[[#This Row],[Sector]]="Financial Services",TRUE,FALSE) -> FALSE | AA13: =IF(Table2[[#This Row],[Market Capitalisation In(Cr)]]>25000,TRUE,FALSE) -> FALSE
B14: CHAMBLFERT | C14: =_xlfn.XLOOKUP(B14,stock_analysis[Stock],stock_analysis[Company_Name]) -> Chambal Fertilizers & Chemicals Limited | D14: =_xlfn.XLOOKUP(B14,stock_analysis[Stock],stock_analysis[Sector]) -> Basic Materials | E14: =_xlfn.XLOOKUP($B14,stock_analysis[Stock],stock_analysis[Industry]) -> Agricultural Inputs | F14: =_xlfn.XLOOKUP($B14,stock_analysis[Stock],stock_analysis[Market_Cap_Cr]) -> 17147.917 | G14: =Imputs!$C$2 -> 0.0667 | H14: =Imputs!$C$3 -> 0.0523 | I14: =_xlfn.XLOOKUP($B14,stock_analysis[Stock],stock_analysis[Beta_Daily]) -> 0.76192181 | J14: =_xlfn.XLOOKUP($B14,stock_analysis[Stock],stock_analysis[Beta_Weekly]) -> 0.9502772 | K14: =_xlfn.XLOOKUP($B14,stock_analysis[Stock],stock_analysis[Beta_Monthly]) -> 1.7737476 | L14: =G14+H14*I14 -> 0.10654851 | M14: =J14*H14+G14 -> 0.1163995 | N14: =K14*H14+G14 -> 0.159467 | O14: =_xlfn.XLOOKUP($B14,stock_analysis[Stock],stock_analysis[Interest_Coverage_Ratio]) -> 75.316763 | P14: {=CHOOSE( _xlfn.IFS(Table2[[#This Row],[Financial Services ]]=TRUE,2,Table2[[#This Row],[FIRM TYPE]]=TRUE,1,Table2[[#This Row],[FIRM TYPE]]=FALSE,3), _xlfn.CHOOSECOLS(_xlfn._xlws.FILTER(Rating1[],(Table2[[#This Row],[Interest Coverage Ratio]]>Rating1[>])*(Table2[[#This Row],[Interest Coverage Ratio]]<Rating1[≤ to])),4), _xlfn.CHOOSECOLS(_xlfn._xlws.FILTER(Rating2[],(Table2[[#This Row],[Interest Coverage Ratio]]>Rating2[greater than])*(Table2[[#This Row],[Interest Coverage Ratio]]<Rating2[≤ to])),4), _xlfn.CHOOSECOLS(_xlfn._xlws.FILTER(Rating3[],(Table2[[#This Row],[Interest Coverage Ratio]]>Rating3[greater than])*(Table2[[#This Row],[Interest Coverage Ratio]]<Rating3[≤ to])),4) )} -> 0.004 | Q14: {=CHOOSE( _xlfn.IFS(Table2[[#This Row],[Financial Services ]]=TRUE,2,Table2[[#This Row],[FIRM TYPE]]=TRUE,1,Table2[[#This Row],[FIRM TYPE]]=FALSE,3), _xlfn.CHOOSECOLS(_xlfn._xlws.FILTER(Rating1[],(Table2[[#This Row],[Interest Coverage Ratio]]>Rating1[>])*(Table2[[#This Row],[Interest Coverage Ratio]]<Rating1[≤ to])),3), _xlfn.CHOOSECOLS(_xlfn._xlws.FILTER(Rating2[],(Table2[[#This Row],[Interest Coverage Ratio]]>Rating2[greater than])*(Table2[[#This Row],[Interest Coverage Ratio]]<Rating2[≤ to])),3), _xlfn.CHOOSECOLS(_xlfn._xlws.FILTER(Rating3[],(Table2[[#This Row],[Interest Coverage Ratio]]>Rating3[greater than])*(Table2[[#This Row],[Interest Coverage Ratio]]<Rating3[≤ to])),3) )} -> Aaa/AAA | R14: =Table2[[#This Row],[Default Spread]]+Table2[[#This Row],[Risk Free Rate]] -> 0.0707 | S14: =_xlfn.XLOOKUP($B14,stock_analysis[Stock],stock_analysis[Market_Cap_Cr]) -> 17147.917 | T14: =_xlfn.XLOOKUP($B14,stock_analysis[Stock],stock_analysis[Total_Debt_Cr]) -> 100.37 | U14: =Table2[[#This Row],[Market Value of Equity]]/(Table2[[#This Row],[Market Value of Equity]]+Table2[[#This Row],[Market Value of Debt]]) -> 0.99418087 | V14: =Table2[[#This Row],[Market Value of Debt]]/(Table2[[#This Row],[Market Value of Equity]]+Table2[[#This Row],[Market Value of Debt]]) -> 0.0058191284 | W14: =(Table2[[#This Row],[Cost of Equity (Daily Beta)]]*Table2[[#This Row],[Weight of Equity]])+(Table2[[#This Row],[Cost of Debt]]*Table2[[#This Row],[Weight of Debt]]) -> 0.1063399 | X14: =(Table2[[#This Row],[Cost of Equity (Weekly Beta)]]*Table2[[#This Row],[Weight of Equity]])+(Table2[[#This Row],[Cost of Debt]]*Table2[[#This Row],[Weight of Debt]]) -> 0.11613357 | Y14: =(Table2[[#This Row],[Cost of Equity (Monthly Beta)]]*Table2[[#This Row],[Weight of Equity]])+(Table2[[#This Row],[Cost of Debt]]*Table2[[#This Row],[Weight of Debt]]) -> 0.15895045 | Z14: =IF(Table2[[#This Row],[Sector]]="Financial Services",TRUE,FALSE) -> FALSE | AA14: =IF(Table2[[#This Row],[Market Capitalisation In(Cr)]]>25000,TRUE,FALSE) -> FALSE
... B133: JAINREC | C133: =_xlfn.XLOOKUP(B133,stock_analysis[Stock],stock_analysis[Company_Name]) -> Jain Resource Recycling Limited | D133: =_xlfn.XLOOKUP(B133,stock_analysis[Stock],stock_analysis[Sector]) -> Basic Materials | E133: =_xlfn.XLOOKUP($B133,stock_analysis[Stock],stock_analysis[Industry]) -> Other Industrial Metals & Mining | F133: =_xlfn.XLOOKUP($B133,stock_analysis[Stock],stock_analysis[Market_Cap_Cr]) -> 13837.941 | G133: =Imputs!$C$2 -> 0.0667 | H133: =Imputs!$C$3 -> 0.0523 | I133: =_xlfn.XLOOKUP($B133,stock_analysis[Stock],stock_analysis[Beta_Daily]) -> 0.78616311 | J133: =_xlfn.XLOOKUP($B133,stock_analysis[Stock],stock_analysis[Beta_Weekly]) -> 1.259266 | K133: =_xlfn.XLOOKUP($B133,stock_analysis[Stock],stock_analysis[Beta_Monthly]) -> 0.72399193 | L133: =G133+H133*I133 -> 0.10781633 | M133: =J133*H133+G133 -> 0.13255961 | N133: =K133*H133+G133 -> 0.10456478 | O133: =_xlfn.XLOOKUP($B133,stock_analysis[Stock],stock_analysis[Interest_Coverage_Ratio]) -> 5.0523249 | P133: {=CHOOSE( _xlfn.IFS(Table2[[#This Row],[Financial Services ]]=TRUE,2,Table2[[#This Row],[FIRM TYPE]]=TRUE,1,Table2[[#This Row],[FIRM TYPE]]=FALSE,3), _xlfn.CHOOSECOLS(_xlfn._xlws.FILTER(Rating1[],(Table2[[#This Row],[Interest Coverage Ratio]]>Rating1[>])*(Table2[[#This Row],[Interest Coverage Ratio]]<Rating1[≤ to])),4), _xlfn.CHOOSECOLS(_xlfn._xlws.FILTER(Rating2[],(Table2[[#This Row],[Interest Coverage Ratio]]>Rating2[greater than])*(Table2[[#This Row],[Interest Coverage Ratio]]<Rating2[≤ to])),4), _xlfn.CHOOSECOLS(_xlfn._xlws.FILTER(Rating3[],(Table2[[#This Row],[Interest Coverage Ratio]]>Rating3[greater than])*(Table2[[#This Row],[Interest Coverage Ratio]]<Rating3[≤ to])),4) )} -> 0.0089 | Q133: {=CHOOSE( _xlfn.IFS(Table2[[#This Row],[Financial Services ]]=TRUE,2,Table2[[#This Row],[FIRM TYPE]]=TRUE,1,Table2[[#This Row],[FIRM TYPE]]=FALSE,3), _xlfn.CHOOSECOLS(_xlfn._xlws.FILTER(Rating1[],(Table2[[#This Row],[Interest Coverage Ratio]]>Rating1[>])*(Table2[[#This Row],[Interest Coverage Ratio]]<Rating1[≤ to])),3), _xlfn.CHOOSECOLS(_xlfn._xlws.FILTER(Rating2[],(Table2[[#This Row],[Interest Coverage Ratio]]>Rating2[greater than])*(Table2[[#This Row],[Interest Coverage Ratio]]<Rating2[≤ to])),3), _xlfn.CHOOSECOLS(_xlfn._xlws.FILTER(Rating3[],(Table2[[#This Row],[Interest Coverage Ratio]]>Rating3[greater than])*(Table2[[#This Row],[Interest Coverage Ratio]]<Rating3[≤ to])),3) )} -> A3/A- | R133: =Table2[[#This Row],[Default Spread]]+Table2[[#This Row],[Risk Free Rate]] -> 0.0756 | S133: =_xlfn.XLOOKUP($B133,stock_analysis[Stock],stock_analysis[Market_Cap_Cr]) -> 13837.941 | T133: =_xlfn.XLOOKUP($B133,stock_analysis[Stock],stock_analysis[Total_Debt_Cr]) -> 1293.571 | U133: =Table2[[#This Row],[Market Value of Equity]]/(Table2[[#This Row],[Market Value of Equity]]+Table2[[#This Row],[Market Value of Debt]]) -> 0.91451145 | V133: =Table2[[#This Row],[Market Value of Debt]]/(Table2[[#This Row],[Market Value of Equity]]+Table2[[#This Row],[Market Value of Debt]]) -> 0.085488546 | W133: =(Table2[[#This Row],[Cost of Equity (Daily Beta)]]*Table2[[#This Row],[Weight of Equity]])+(Table2[[#This Row],[Cost of Debt]]*Table2[[#This Row],[Weight of Debt]]) -> 0.1050622 | X133: =(Table2[[#This Row],[Cost of Equity (Weekly Beta)]]*Table2[[#This Row],[Weight of Equity]])+(Table2[[#This Row],[Cost of Debt]]*Table2[[#This Row],[Weight of Debt]]) -> 0.12769022 | Y133: =(Table2[[#This Row],[Cost of Equity (Monthly Beta)]]*Table2[[#This Row],[Weight of Equity]])+(Table2[[#This Row],[Cost of Debt]]*Table2[[#This Row],[Weight of Debt]]) -> 0.10208862 | Z133: =IF(Table2[[#This Row],[Sector]]="Financial Services",TRUE,FALSE) -> FALSE | AA133: =IF(Table2[[#This Row],[Market Capitalisation In(Cr)]]>25000,TRUE,FALSE) -> FALSE
B134: 20MICRONS | C134: =_xlfn.XLOOKUP(B134,stock_analysis[Stock],stock_analysis[Company_Name]) -> 20 Microns Limited | D134: =_xlfn.XLOOKUP($B134,stock_analysis[Stock],stock_analysis[Sector]) -> Basic Materials | E134: =_xlfn.XLOOKUP($B134,stock_analysis[Stock],stock_analysis[Industry]) -> Other Industrial Metals & Mining | F134: =_xlfn.XLOOKUP($B134,stock_analysis[Stock],stock_analysis[Market_Cap_Cr]) -> 589.33535 | G134: =Imputs!$C$2 -> 0.0667 | H134: =Imputs!$C$3 -> 0.0523 | I134: =_xlfn.XLOOKUP($B134,stock_analysis[Stock],stock_analysis[Beta_Daily]) -> 1.1950363 | J134: =_xlfn.XLOOKUP($B134,stock_analysis[Stock],stock_analysis[Beta_Weekly]) -> 1.37515 | K134: =_xlfn.XLOOKUP($B134,stock_analysis[Stock],stock_analysis[Beta_Monthly]) -> 8.2148172 | L134: =G134+H134*I134 -> 0.1292004 | M134: =J134*H134+G134 -> 0.13862035 | N134: =K134*H134+G134 -> 0.49633494 | O134: =_xlfn.XLOOKUP($B134,stock_analysis[Stock],stock_analysis[Interest_Coverage_Ratio]) -> 8.3028055 | P134: {=CHOOSE( _xlfn.IFS(Table2[[#This Row],[Financial Services ]]=TRUE,2,Table2[[#This Row],[FIRM TYPE]]=TRUE,1,Table2[[#This Row],[FIRM TYPE]]=FALSE,3), _xlfn.CHOOSECOLS(_xlfn._xlws.FILTER(Rating1[],(Table2[[#This Row],[Interest Coverage Ratio]]>Rating1[>])*(Table2[[#This Row],[Interest Coverage Ratio]]<Rating1[≤ to])),4), _xlfn.CHOOSECOLS(_xlfn._xlws.FILTER(Rating2[],(Table2[[#This Row],[Interest Coverage Ratio]]>Rating2[greater than])*(Table2[[#This Row],[Interest Coverage Ratio]]<Rating2[≤ to])),4), _xlfn.CHOOSECOLS(_xlfn._xlws.FILTER(Rating3[],(Table2[[#This Row],[Interest Coverage Ratio]]>Rating3[greater than])*(Table2[[#This Row],[Interest Coverage Ratio]]<Rating3[≤ to])),4) )} -> 0.007 | Q134: {=CHOOSE( _xlfn.IFS(Table2[[#This Row],[Financial Services ]]=TRUE,2,Table2[[#This Row],[FIRM TYPE]]=TRUE,1,Table2[[#This Row],[FIRM TYPE]]=FALSE,3), _xlfn.CHOOSECOLS(_xlfn._xlws.FILTER(Rating1[],(Table2[[#This Row],[Interest Coverage Ratio]]>Rating1[>])*(Table2[[#This Row],[Interest Coverage Ratio]]<Rating1[≤ to])),3), _xlfn.CHOOSECOLS(_xlfn._xlws.FILTER(Rating2[],(Table2[[#This Row],[Interest Coverage Ratio]]>Rating2[greater than])*(Table2[[#This Row],[Interest Coverage Ratio]]<Rating2[≤ to])),3), _xlfn.CHOOSECOLS(_xlfn._xlws.FILTER(Rating3[],(Table2[[#This Row],[Interest Coverage Ratio]]>Rating3[greater than])*(Table2[[#This Row],[Interest Coverage Ratio]]<Rating3[≤ to])),3) )} -> A1/A+ | R134: =Table2[[#This Row],[Default Spread]]+Table2[[#This Row],[Risk Free Rate]] -> 0.0737 | S134: =_xlfn.XLOOKUP($B134,stock_analysis[Stock],stock_analysis[Market_Cap_Cr]) -> 589.33535 | T134: =_xlfn.XLOOKUP($B134,stock_analysis[Stock],stock_analysis[Total_Debt_Cr]) -> 163.3658 | U134: =Table2[[#This Row],[Market Value of Equity]]/(Table2[[#This Row],[Market Value of Equity]]+Table2[[#This Row],[Market Value of Debt]]) -> 0.78296061 | V134: =Table2[[#This Row],[Market Value of Debt]]/(Table2[[#This Row],[Market Value of Equity]]+Table2[[#This Row],[Market Value of Debt]]) -> 0.21703939 | W134: =(Table2[[#This Row],[Cost of Equity (Daily Beta)]]*Table2[[#This Row],[Weight of Equity]])+(Table2[[#This Row],[Cost of Debt]]*Table2[[#This Row],[Weight of Debt]]) -> 0.11715462 | X134: =(Table2[[#This Row],[Cost of Equity (Weekly Beta)]]*Table2[[#This Row],[Weight of Equity]])+(Table2[[#This Row],[Cost of Debt]]*Table2[[#This Row],[Weight of Debt]]) -> 0.12453007 | Y134: =(Table2[[#This Row],[Cost of Equity (Monthly Beta)]]*Table2[[#This Row],[Weight of Equity]])+(Table2[[#This Row],[Cost of Debt]]*Table2[[#This Row],[Weight of Debt]]) -> 0.40460651 | Z134: =IF(Table2[[#This Row],[Sector]]="Financial Services",TRUE,FALSE) -> FALSE | AA134: =IF(Table2[[#This Row],[Market Capitalisation In(Cr)]]>25000,TRUE,FALSE) -> FALSE
B135: IMFA | C135: =_xlfn.XLOOKUP(B135,stock_analysis[Stock],stock_analysis[Company_Name]) -> Indian Metals & Ferro Alloys Limited | D135: =_xlfn.XLOOKUP(B135,stock_analysis[Stock],stock_analysis[Sector]) -> Basic Materials | E135: =_xlfn.XLOOKUP($B135,stock_analysis[Stock],stock_analysis[Industry]) -> Other Industrial Metals & Mining | F135: =_xlfn.XLOOKUP($B135,stock_analysis[Stock],stock_analysis[Market_Cap_Cr]) -> 6378.6467 | G135: =Imputs!$C$2 -> 0.0667 | H135: =Imputs!$C$3 -> 0.0523 | I135: =_xlfn.XLOOKUP($B135,stock_analysis[Stock],stock_analysis[Beta_Daily]) -> 1.0561701 | J135: =_xlfn.XLOOKUP($B135,stock_analysis[Stock],stock_analysis[Beta_Weekly]) -> 1.7206584 | K135: =_xlfn.XLOOKUP($B135,stock_analysis[Stock],stock_analysis[Beta_Monthly]) -> 0.7156995 | L135: =G135+H135*I135 -> 0.12193769 | M135: =J135*H135+G135 -> 0.15669044 | N135: =K135*H135+G135 -> 0.10413108 | O135: =_xlfn.XLOOKUP($B135,stock_analysis[Stock],stock_analysis[Interest_Coverage_Ratio]) -> 23.323491 | P135: {=CHOOSE( _xlfn.IFS(Table2[[#This Row],[Financial Services ]]=TRUE,2,Table2[[#This Row],[FIRM TYPE]]=TRUE,1,Table2[[#This Row],[FIRM TYPE]]=FALSE,3), _xlfn.CHOOSECOLS(_xlfn._xlws.FILTER(Rating1[],(Table2[[#This Row],[Interest Coverage Ratio]]>Rating1[>])*(Table2[[#This Row],[Interest Coverage Ratio]]<Rating1[≤ to])),4), _xlfn.CHOOSECOLS(_xlfn._xlws.FILTER(Rating2[],(Table2[[#This Row],[Interest Coverage Ratio]]>Rating2[greater than])*(Table2[[#This Row],[Interest Coverage Ratio]]<Rating2[≤ to])),4), _xlfn.CHOOSECOLS(_xlfn._xlws.FILTER(Rating3[],(Table2[[#This Row],[Interest Coverage Ratio]]>Rating3[greater than])*(Table2[[#This Row],[Interest Coverage Ratio]]<Rating3[≤ to])),4) )} -> 0.004 | Q135: {=CHOOSE( _xlfn.IFS(Table2[[#This Row],[Financial Services ]]=TRUE,2,Table2[[#This Row],[FIRM TYPE]]=TRUE,1,Table2[[#This Row],[FIRM TYPE]]=FALSE,3), _xlfn.CHOOSECOLS(_xlfn._xlws.FILTER(Rating1[],(Table2[[#This Row],[Interest Coverage Ratio]]>Rating1[>])*(Table2[[#This Row],[Interest Coverage Ratio]]<Rating1[≤ to])),3), _xlfn.CHOOSECOLS(_xlfn._xlws.FILTER(Rating2[],(Table2[[#This Row],[Interest Coverage Ratio]]>Rating2[greater than])*(Table2[[#This Row],[Interest Coverage Ratio]]<Rating2[≤ to])),3), _xlfn.CHOOSECOLS(_xlfn._xlws.FILTER(Rating3[],(Table2[[#This Row],[Interest Coverage Ratio]]>Rating3[greater than])*(Table2[[#This Row],[Interest Coverage Ratio]]<Rating3[≤ to])),3) )} -> Aaa/AAA | R135: =Table2[[#This Row],[Default Spread]]+Table2[[#This Row],[Risk Free Rate]] -> 0.0707 | S135: =_xlfn.XLOOKUP($B135,stock_analysis[Stock],stock_analysis[Market_Cap_Cr]) -> 6378.6467 | T135: =_xlfn.XLOOKUP($B135,stock_analysis[Stock],stock_analysis[Total_Debt_Cr]) -> 435.32001 | U135: =Table2[[#This Row],[Market Value of Equity]]/(Table2[[#This Row],[Market Value of Equity]]+Table2[[#This Row],[Market Value of Debt]]) -> 0.93611357 | V135: =Table2[[#This Row],[Market Value of Debt]]/(Table2[[#This Row],[Market Value of Equity]]+Table2[[#This Row],[Market Value of Debt]]) -> 0.06388643 | W135: =(Table2[[#This Row],[Cost of Equity (Daily Beta)]]*Table2[[#This Row],[Weight of Equity]])+(Table2[[#This Row],[Cost of Debt]]*Table2[[#This Row],[Weight of Debt]]) -> 0.1186643 | X135: =(Table2[[#This Row],[Cost of Equity (Weekly Beta)]]*Table2[[#This Row],[Weight of Equity]])+(Table2[[#This Row],[Cost of Debt]]*Table2[[#This Row],[Weight of Debt]]) -> 0.15119681 | Y135: =(Table2[[#This Row],[Cost of Equity (Monthly Beta)]]*Table2[[#This Row],[Weight of Equity]])+(Table2[[#This Row],[Cost of Debt]]*Table2[[#This Row],[Weight of Debt]]) -> 0.10199529 | Z135: =IF(Table2[[#This Row],[Sector]]="Financial Services",TRUE,FALSE) -> FALSE | AA135: =IF(Table2[[#This Row],[Market Capitalisation In(Cr)]]>25000,TRUE,FALSE) -> FALSE
